2023-01-03 18:41:32,772 ERROR: Exception on /user/john [GET] [in C:\Users\FaheemNoorani\AppData\Local\Programs\Python\Python311\Lib\site-packages\flask\app.py:1741]
Traceback (most recent call last):
  File "C:\Users\FaheemNoorani\AppData\Local\Programs\Python\Python311\Lib\site-packages\flask\app.py", line 2525, in wsgi_app
    response = self.full_dispatch_request()
               ^^^^^^^^^^^^^^^^^^^^^^^^^^^^
  File "C:\Users\FaheemNoorani\AppData\Local\Programs\Python\Python311\Lib\site-packages\flask\app.py", line 1822, in full_dispatch_request
    rv = self.handle_user_exception(e)
         ^^^^^^^^^^^^^^^^^^^^^^^^^^^^^
  File "C:\Users\FaheemNoorani\AppData\Local\Programs\Python\Python311\Lib\site-packages\flask\app.py", line 1820, in full_dispatch_request
    rv = self.dispatch_request()
         ^^^^^^^^^^^^^^^^^^^^^^^
  File "C:\Users\FaheemNoorani\AppData\Local\Programs\Python\Python311\Lib\site-packages\flask\app.py", line 1796, in dispatch_request
    return self.ensure_sync(self.view_functions[rule.endpoint])(**view_args)
           ^^^^^^^^^^^^^^^^^^^^^^^^^^^^^^^^^^^^^^^^^^^^^^^^^^^^^^^^^^^^^^^^^
  File "C:\Users\FaheemNoorani\AppData\Local\Programs\Python\Python311\Lib\site-packages\flask_login\utils.py", line 290, in decorated_view
    return current_app.ensure_sync(func)(*args, **kwargs)
           ^^^^^^^^^^^^^^^^^^^^^^^^^^^^^^^^^^^^^^^^^^^^^^
  File "C:\Users\FaheemNoorani\PycharmProjects\GiftExchange\app\routes.py", line 78, in user
    posts = current_user.followed_posts.all()
            ^^^^^^^^^^^^^^^^^^^^^^^^^^^^^^^
AttributeError: 'function' object has no attribute 'all'
2023-01-03 18:45:29,150 INFO: Microblog startup [in C:\Users\FaheemNoorani\PycharmProjects\GiftExchange\app\__init__.py:48]
2023-01-03 18:45:33,812 ERROR: Exception on /user/john [GET] [in C:\Users\FaheemNoorani\AppData\Local\Programs\Python\Python311\Lib\site-packages\flask\app.py:1741]
Traceback (most recent call last):
  File "C:\Users\FaheemNoorani\AppData\Local\Programs\Python\Python311\Lib\site-packages\sqlalchemy\sql\base.py", line 1694, in _entity_namespace_key
    return getattr(ns, key)
           ^^^^^^^^^^^^^^^^
AttributeError: type object 'Post' has no attribute 'username'

The above exception was the direct cause of the following exception:

Traceback (most recent call last):
  File "C:\Users\FaheemNoorani\AppData\Local\Programs\Python\Python311\Lib\site-packages\flask\app.py", line 2525, in wsgi_app
    response = self.full_dispatch_request()
               ^^^^^^^^^^^^^^^^^^^^^^^^^^^^
  File "C:\Users\FaheemNoorani\AppData\Local\Programs\Python\Python311\Lib\site-packages\flask\app.py", line 1822, in full_dispatch_request
    rv = self.handle_user_exception(e)
         ^^^^^^^^^^^^^^^^^^^^^^^^^^^^^
  File "C:\Users\FaheemNoorani\AppData\Local\Programs\Python\Python311\Lib\site-packages\flask\app.py", line 1820, in full_dispatch_request
    rv = self.dispatch_request()
         ^^^^^^^^^^^^^^^^^^^^^^^
  File "C:\Users\FaheemNoorani\AppData\Local\Programs\Python\Python311\Lib\site-packages\flask\app.py", line 1796, in dispatch_request
    return self.ensure_sync(self.view_functions[rule.endpoint])(**view_args)
           ^^^^^^^^^^^^^^^^^^^^^^^^^^^^^^^^^^^^^^^^^^^^^^^^^^^^^^^^^^^^^^^^^
  File "C:\Users\FaheemNoorani\AppData\Local\Programs\Python\Python311\Lib\site-packages\flask_login\utils.py", line 290, in decorated_view
    return current_app.ensure_sync(func)(*args, **kwargs)
           ^^^^^^^^^^^^^^^^^^^^^^^^^^^^^^^^^^^^^^^^^^^^^^
  File "C:\Users\FaheemNoorani\PycharmProjects\GiftExchange\app\routes.py", line 79, in user
    posts = Post.query.filter_by(username=current_user.username)
            ^^^^^^^^^^^^^^^^^^^^^^^^^^^^^^^^^^^^^^^^^^^^^^^^^^^^
  File "C:\Users\FaheemNoorani\AppData\Local\Programs\Python\Python311\Lib\site-packages\sqlalchemy\orm\query.py", line 1806, in filter_by
    clauses = [
              ^
  File "C:\Users\FaheemNoorani\AppData\Local\Programs\Python\Python311\Lib\site-packages\sqlalchemy\orm\query.py", line 1807, in <listcomp>
    _entity_namespace_key(from_entity, key) == value
    ^^^^^^^^^^^^^^^^^^^^^^^^^^^^^^^^^^^^^^^
  File "C:\Users\FaheemNoorani\AppData\Local\Programs\Python\Python311\Lib\site-packages\sqlalchemy\sql\base.py", line 1696, in _entity_namespace_key
    util.raise_(
  File "C:\Users\FaheemNoorani\AppData\Local\Programs\Python\Python311\Lib\site-packages\sqlalchemy\util\compat.py", line 211, in raise_
    raise exception
sqlalchemy.exc.InvalidRequestError: Entity namespace for "post" has no property "username"
2023-01-03 18:46:24,135 INFO: Microblog startup [in C:\Users\FaheemNoorani\PycharmProjects\GiftExchange\app\__init__.py:48]
2023-01-03 18:47:00,572 INFO: Microblog startup [in C:\Users\FaheemNoorani\PycharmProjects\GiftExchange\app\__init__.py:48]
2023-01-03 18:47:04,318 ERROR: Exception on /user/john [GET] [in C:\Users\FaheemNoorani\AppData\Local\Programs\Python\Python311\Lib\site-packages\flask\app.py:1741]
Traceback (most recent call last):
  File "C:\Users\FaheemNoorani\AppData\Local\Programs\Python\Python311\Lib\site-packages\flask\app.py", line 2525, in wsgi_app
    response = self.full_dispatch_request()
               ^^^^^^^^^^^^^^^^^^^^^^^^^^^^
  File "C:\Users\FaheemNoorani\AppData\Local\Programs\Python\Python311\Lib\site-packages\flask\app.py", line 1822, in full_dispatch_request
    rv = self.handle_user_exception(e)
         ^^^^^^^^^^^^^^^^^^^^^^^^^^^^^
  File "C:\Users\FaheemNoorani\AppData\Local\Programs\Python\Python311\Lib\site-packages\flask\app.py", line 1820, in full_dispatch_request
    rv = self.dispatch_request()
         ^^^^^^^^^^^^^^^^^^^^^^^
  File "C:\Users\FaheemNoorani\AppData\Local\Programs\Python\Python311\Lib\site-packages\flask\app.py", line 1796, in dispatch_request
    return self.ensure_sync(self.view_functions[rule.endpoint])(**view_args)
           ^^^^^^^^^^^^^^^^^^^^^^^^^^^^^^^^^^^^^^^^^^^^^^^^^^^^^^^^^^^^^^^^^
  File "C:\Users\FaheemNoorani\AppData\Local\Programs\Python\Python311\Lib\site-packages\flask_login\utils.py", line 290, in decorated_view
    return current_app.ensure_sync(func)(*args, **kwargs)
           ^^^^^^^^^^^^^^^^^^^^^^^^^^^^^^^^^^^^^^^^^^^^^^
  File "C:\Users\FaheemNoorani\PycharmProjects\GiftExchange\app\routes.py", line 71, in user
    return render_template('user.html', user=user, posts=posts, form=form)
                                                                     ^^^^
NameError: name 'form' is not defined
2023-01-03 18:47:26,705 ERROR: Exception on /index [GET] [in C:\Users\FaheemNoorani\AppData\Local\Programs\Python\Python311\Lib\site-packages\flask\app.py:1741]
Traceback (most recent call last):
  File "C:\Users\FaheemNoorani\AppData\Local\Programs\Python\Python311\Lib\site-packages\flask\app.py", line 2525, in wsgi_app
    response = self.full_dispatch_request()
               ^^^^^^^^^^^^^^^^^^^^^^^^^^^^
  File "C:\Users\FaheemNoorani\AppData\Local\Programs\Python\Python311\Lib\site-packages\flask\app.py", line 1822, in full_dispatch_request
    rv = self.handle_user_exception(e)
         ^^^^^^^^^^^^^^^^^^^^^^^^^^^^^
  File "C:\Users\FaheemNoorani\AppData\Local\Programs\Python\Python311\Lib\site-packages\flask\app.py", line 1820, in full_dispatch_request
    rv = self.dispatch_request()
         ^^^^^^^^^^^^^^^^^^^^^^^
  File "C:\Users\FaheemNoorani\AppData\Local\Programs\Python\Python311\Lib\site-packages\flask\app.py", line 1796, in dispatch_request
    return self.ensure_sync(self.view_functions[rule.endpoint])(**view_args)
           ^^^^^^^^^^^^^^^^^^^^^^^^^^^^^^^^^^^^^^^^^^^^^^^^^^^^^^^^^^^^^^^^^
  File "C:\Users\FaheemNoorani\AppData\Local\Programs\Python\Python311\Lib\site-packages\flask_login\utils.py", line 290, in decorated_view
    return current_app.ensure_sync(func)(*args, **kwargs)
           ^^^^^^^^^^^^^^^^^^^^^^^^^^^^^^^^^^^^^^^^^^^^^^
  File "C:\Users\FaheemNoorani\PycharmProjects\GiftExchange\app\routes.py", line 21, in index
    posts = current_user.followed_posts.all()
            ^^^^^^^^^^^^^^^^^^^^^^^^^^^^^^^
AttributeError: 'function' object has no attribute 'all'
2023-01-03 18:47:27,463 ERROR: Exception on /user/john [GET] [in C:\Users\FaheemNoorani\AppData\Local\Programs\Python\Python311\Lib\site-packages\flask\app.py:1741]
Traceback (most recent call last):
  File "C:\Users\FaheemNoorani\AppData\Local\Programs\Python\Python311\Lib\site-packages\flask\app.py", line 2525, in wsgi_app
    response = self.full_dispatch_request()
               ^^^^^^^^^^^^^^^^^^^^^^^^^^^^
  File "C:\Users\FaheemNoorani\AppData\Local\Programs\Python\Python311\Lib\site-packages\flask\app.py", line 1822, in full_dispatch_request
    rv = self.handle_user_exception(e)
         ^^^^^^^^^^^^^^^^^^^^^^^^^^^^^
  File "C:\Users\FaheemNoorani\AppData\Local\Programs\Python\Python311\Lib\site-packages\flask\app.py", line 1820, in full_dispatch_request
    rv = self.dispatch_request()
         ^^^^^^^^^^^^^^^^^^^^^^^
  File "C:\Users\FaheemNoorani\AppData\Local\Programs\Python\Python311\Lib\site-packages\flask\app.py", line 1796, in dispatch_request
    return self.ensure_sync(self.view_functions[rule.endpoint])(**view_args)
           ^^^^^^^^^^^^^^^^^^^^^^^^^^^^^^^^^^^^^^^^^^^^^^^^^^^^^^^^^^^^^^^^^
  File "C:\Users\FaheemNoorani\AppData\Local\Programs\Python\Python311\Lib\site-packages\flask_login\utils.py", line 290, in decorated_view
    return current_app.ensure_sync(func)(*args, **kwargs)
           ^^^^^^^^^^^^^^^^^^^^^^^^^^^^^^^^^^^^^^^^^^^^^^
  File "C:\Users\FaheemNoorani\PycharmProjects\GiftExchange\app\routes.py", line 71, in user
    return render_template('user.html', user=user, posts=posts, form=form)
                                                                     ^^^^
NameError: name 'form' is not defined
